{
 "cells": [
  {
   "cell_type": "code",
   "execution_count": null,
   "id": "504eebe0",
   "metadata": {},
   "outputs": [],
   "source": [
    "# !pip install librosa\n",
    "\n",
    "# !pip install --user --upgrade matplotlib"
   ]
  },
  {
   "cell_type": "code",
   "execution_count": null,
   "id": "8314e81e",
   "metadata": {},
   "outputs": [],
   "source": [
    "# !pip install scipy"
   ]
  },
  {
   "cell_type": "code",
   "execution_count": 1,
   "id": "0b032a06",
   "metadata": {},
   "outputs": [],
   "source": [
    "# !pip install matplotlib"
   ]
  },
  {
   "cell_type": "code",
   "execution_count": 2,
   "id": "527949a2",
   "metadata": {},
   "outputs": [
    {
     "data": {
      "text/plain": [
       "'0.10.0.post2'"
      ]
     },
     "execution_count": 2,
     "metadata": {},
     "output_type": "execute_result"
    }
   ],
   "source": [
    "import librosa\n",
    "librosa.__version__"
   ]
  },
  {
   "cell_type": "code",
   "execution_count": null,
   "id": "743ddcdc",
   "metadata": {},
   "outputs": [],
   "source": []
  },
  {
   "cell_type": "code",
   "execution_count": null,
   "id": "b2b74cb0",
   "metadata": {},
   "outputs": [
    {
     "name": "stderr",
     "output_type": "stream",
     "text": [
      "ERROR:root:Internal Python error in the inspect module.\n",
      "Below is the traceback from this internal error.\n",
      "\n",
      "ERROR:root:Internal Python error in the inspect module.\n",
      "Below is the traceback from this internal error.\n",
      "\n",
      "ERROR:root:Internal Python error in the inspect module.\n",
      "Below is the traceback from this internal error.\n",
      "\n"
     ]
    },
    {
     "name": "stdout",
     "output_type": "stream",
     "text": [
      "Traceback (most recent call last):\n",
      "  File \"C:\\Users\\yashd\\anaconda3\\lib\\site-packages\\IPython\\core\\interactiveshell.py\", line 3457, in run_code\n",
      "    exec(code_obj, self.user_global_ns, self.user_ns)\n",
      "  File \"C:\\Users\\yashd\\AppData\\Local\\Temp\\ipykernel_14992\\1699537367.py\", line 5, in <module>\n",
      "    import librosa.display\n",
      "  File \"C:\\Users\\yashd\\anaconda3\\lib\\site-packages\\librosa\\display.py\", line 90, in <module>\n",
      "    class TimeFormatter(mplticker.Formatter):\n",
      "  File \"C:\\Users\\yashd\\anaconda3\\lib\\importlib\\util.py\", line 245, in __getattribute__\n",
      "    self.__spec__.loader.exec_module(self)\n",
      "  File \"C:\\Users\\yashd\\anaconda3\\lib\\site-packages\\matplotlib\\ticker.py\", line 138, in <module>\n",
      "    from matplotlib import transforms as mtransforms\n",
      "  File \"C:\\Users\\yashd\\anaconda3\\lib\\site-packages\\matplotlib\\transforms.py\", line 49, in <module>\n",
      "    from matplotlib._path import (\n",
      "ImportError: DLL load failed while importing _path: The specified module could not be found.\n",
      "\n",
      "During handling of the above exception, another exception occurred:\n",
      "\n",
      "Traceback (most recent call last):\n",
      "  File \"C:\\Users\\yashd\\anaconda3\\lib\\site-packages\\IPython\\core\\interactiveshell.py\", line 2077, in showtraceback\n",
      "    stb = value._render_traceback_()\n",
      "AttributeError: 'ImportError' object has no attribute '_render_traceback_'\n",
      "\n",
      "During handling of the above exception, another exception occurred:\n",
      "\n",
      "Traceback (most recent call last):\n",
      "  File \"C:\\Users\\yashd\\anaconda3\\lib\\site-packages\\IPython\\core\\ultratb.py\", line 1101, in get_records\n",
      "    return _fixed_getinnerframes(etb, number_of_lines_of_context, tb_offset)\n",
      "  File \"C:\\Users\\yashd\\anaconda3\\lib\\site-packages\\IPython\\core\\ultratb.py\", line 248, in wrapped\n",
      "    return f(*args, **kwargs)\n",
      "  File \"C:\\Users\\yashd\\anaconda3\\lib\\site-packages\\IPython\\core\\ultratb.py\", line 281, in _fixed_getinnerframes\n",
      "    records = fix_frame_records_filenames(inspect.getinnerframes(etb, context))\n",
      "  File \"C:\\Users\\yashd\\anaconda3\\lib\\inspect.py\", line 1543, in getinnerframes\n",
      "    frameinfo = (tb.tb_frame,) + getframeinfo(tb, context)\n",
      "  File \"C:\\Users\\yashd\\anaconda3\\lib\\inspect.py\", line 1501, in getframeinfo\n",
      "    filename = getsourcefile(frame) or getfile(frame)\n",
      "  File \"C:\\Users\\yashd\\anaconda3\\lib\\inspect.py\", line 709, in getsourcefile\n",
      "    if getattr(getmodule(object, filename), '__loader__', None) is not None:\n",
      "  File \"C:\\Users\\yashd\\anaconda3\\lib\\inspect.py\", line 746, in getmodule\n",
      "    if ismodule(module) and hasattr(module, '__file__'):\n",
      "  File \"C:\\Users\\yashd\\anaconda3\\lib\\importlib\\util.py\", line 245, in __getattribute__\n",
      "    self.__spec__.loader.exec_module(self)\n",
      "  File \"<frozen importlib._bootstrap_external>\", line 850, in exec_module\n",
      "  File \"<frozen importlib._bootstrap>\", line 228, in _call_with_frames_removed\n",
      "  File \"C:\\Users\\yashd\\anaconda3\\lib\\site-packages\\matplotlib\\cm.py\", line 25, in <module>\n",
      "    from matplotlib import _api, colors, cbook, scale\n",
      "  File \"C:\\Users\\yashd\\anaconda3\\lib\\site-packages\\matplotlib\\colors.py\", line 56, in <module>\n",
      "    from matplotlib import _api, _cm, cbook, scale\n",
      "  File \"C:\\Users\\yashd\\anaconda3\\lib\\site-packages\\matplotlib\\scale.py\", line 22, in <module>\n",
      "    from matplotlib.ticker import (\n",
      "ImportError: cannot import name 'NullFormatter' from 'matplotlib.ticker' (C:\\Users\\yashd\\anaconda3\\lib\\site-packages\\matplotlib\\ticker.py)\n",
      "Traceback (most recent call last):\n",
      "  File \"C:\\Users\\yashd\\anaconda3\\lib\\site-packages\\IPython\\core\\interactiveshell.py\", line 3457, in run_code\n",
      "    exec(code_obj, self.user_global_ns, self.user_ns)\n",
      "  File \"C:\\Users\\yashd\\AppData\\Local\\Temp\\ipykernel_14992\\1699537367.py\", line 5, in <module>\n",
      "    import librosa.display\n",
      "  File \"C:\\Users\\yashd\\anaconda3\\lib\\site-packages\\librosa\\display.py\", line 90, in <module>\n",
      "    class TimeFormatter(mplticker.Formatter):\n",
      "  File \"C:\\Users\\yashd\\anaconda3\\lib\\importlib\\util.py\", line 245, in __getattribute__\n",
      "    self.__spec__.loader.exec_module(self)\n",
      "  File \"C:\\Users\\yashd\\anaconda3\\lib\\site-packages\\matplotlib\\ticker.py\", line 138, in <module>\n",
      "    from matplotlib import transforms as mtransforms\n",
      "  File \"C:\\Users\\yashd\\anaconda3\\lib\\site-packages\\matplotlib\\transforms.py\", line 49, in <module>\n",
      "    from matplotlib._path import (\n",
      "ImportError: DLL load failed while importing _path: The specified module could not be found.\n",
      "\n",
      "During handling of the above exception, another exception occurred:\n",
      "\n",
      "Traceback (most recent call last):\n",
      "  File \"C:\\Users\\yashd\\anaconda3\\lib\\site-packages\\IPython\\core\\interactiveshell.py\", line 2077, in showtraceback\n",
      "    stb = value._render_traceback_()\n",
      "AttributeError: 'ImportError' object has no attribute '_render_traceback_'\n",
      "\n",
      "During handling of the above exception, another exception occurred:\n",
      "\n",
      "Traceback (most recent call last):\n",
      "  File \"C:\\Users\\yashd\\anaconda3\\lib\\site-packages\\IPython\\core\\interactiveshell.py\", line 3377, in run_ast_nodes\n",
      "    if (await self.run_code(code, result,  async_=asy)):\n",
      "  File \"C:\\Users\\yashd\\anaconda3\\lib\\site-packages\\IPython\\core\\interactiveshell.py\", line 3474, in run_code\n",
      "    self.showtraceback(running_compiled_code=True)\n",
      "  File \"C:\\Users\\yashd\\anaconda3\\lib\\site-packages\\IPython\\core\\interactiveshell.py\", line 2079, in showtraceback\n",
      "    stb = self.InteractiveTB.structured_traceback(etype,\n",
      "  File \"C:\\Users\\yashd\\anaconda3\\lib\\site-packages\\IPython\\core\\ultratb.py\", line 1367, in structured_traceback\n",
      "    return FormattedTB.structured_traceback(\n",
      "  File \"C:\\Users\\yashd\\anaconda3\\lib\\site-packages\\IPython\\core\\ultratb.py\", line 1267, in structured_traceback\n",
      "    return VerboseTB.structured_traceback(\n",
      "  File \"C:\\Users\\yashd\\anaconda3\\lib\\site-packages\\IPython\\core\\ultratb.py\", line 1124, in structured_traceback\n",
      "    formatted_exception = self.format_exception_as_a_whole(etype, evalue, etb, number_of_lines_of_context,\n",
      "  File \"C:\\Users\\yashd\\anaconda3\\lib\\site-packages\\IPython\\core\\ultratb.py\", line 1082, in format_exception_as_a_whole\n",
      "    last_unique, recursion_repeat = find_recursion(orig_etype, evalue, records)\n",
      "  File \"C:\\Users\\yashd\\anaconda3\\lib\\site-packages\\IPython\\core\\ultratb.py\", line 382, in find_recursion\n",
      "    return len(records), 0\n",
      "TypeError: object of type 'NoneType' has no len()\n",
      "\n",
      "During handling of the above exception, another exception occurred:\n",
      "\n",
      "Traceback (most recent call last):\n",
      "  File \"C:\\Users\\yashd\\anaconda3\\lib\\site-packages\\IPython\\core\\interactiveshell.py\", line 2077, in showtraceback\n",
      "    stb = value._render_traceback_()\n",
      "AttributeError: 'TypeError' object has no attribute '_render_traceback_'\n",
      "\n",
      "During handling of the above exception, another exception occurred:\n",
      "\n",
      "Traceback (most recent call last):\n",
      "  File \"C:\\Users\\yashd\\anaconda3\\lib\\site-packages\\IPython\\core\\ultratb.py\", line 1101, in get_records\n",
      "    return _fixed_getinnerframes(etb, number_of_lines_of_context, tb_offset)\n",
      "  File \"C:\\Users\\yashd\\anaconda3\\lib\\site-packages\\IPython\\core\\ultratb.py\", line 248, in wrapped\n",
      "    return f(*args, **kwargs)\n",
      "  File \"C:\\Users\\yashd\\anaconda3\\lib\\site-packages\\IPython\\core\\ultratb.py\", line 281, in _fixed_getinnerframes\n",
      "    records = fix_frame_records_filenames(inspect.getinnerframes(etb, context))\n",
      "  File \"C:\\Users\\yashd\\anaconda3\\lib\\inspect.py\", line 1543, in getinnerframes\n",
      "    frameinfo = (tb.tb_frame,) + getframeinfo(tb, context)\n",
      "  File \"C:\\Users\\yashd\\anaconda3\\lib\\inspect.py\", line 1501, in getframeinfo\n",
      "    filename = getsourcefile(frame) or getfile(frame)\n",
      "  File \"C:\\Users\\yashd\\anaconda3\\lib\\inspect.py\", line 709, in getsourcefile\n",
      "    if getattr(getmodule(object, filename), '__loader__', None) is not None:\n",
      "  File \"C:\\Users\\yashd\\anaconda3\\lib\\inspect.py\", line 746, in getmodule\n",
      "    if ismodule(module) and hasattr(module, '__file__'):\n",
      "  File \"C:\\Users\\yashd\\anaconda3\\lib\\importlib\\util.py\", line 245, in __getattribute__\n",
      "    self.__spec__.loader.exec_module(self)\n",
      "  File \"<frozen importlib._bootstrap_external>\", line 850, in exec_module\n",
      "  File \"<frozen importlib._bootstrap>\", line 228, in _call_with_frames_removed\n",
      "  File \"C:\\Users\\yashd\\anaconda3\\lib\\site-packages\\matplotlib\\axes\\__init__.py\", line 1, in <module>\n",
      "    from . import _base\n",
      "  File \"C:\\Users\\yashd\\anaconda3\\lib\\site-packages\\matplotlib\\axes\\_base.py\", line 14, in <module>\n",
      "    from matplotlib import _api, cbook, _docstring, offsetbox\n",
      "  File \"C:\\Users\\yashd\\anaconda3\\lib\\site-packages\\matplotlib\\offsetbox.py\", line 31, in <module>\n",
      "    import matplotlib.artist as martist\n",
      "  File \"C:\\Users\\yashd\\anaconda3\\lib\\site-packages\\matplotlib\\artist.py\", line 15, in <module>\n",
      "    from .colors import BoundaryNorm\n",
      "  File \"C:\\Users\\yashd\\anaconda3\\lib\\site-packages\\matplotlib\\colors.py\", line 56, in <module>\n",
      "    from matplotlib import _api, _cm, cbook, scale\n",
      "  File \"C:\\Users\\yashd\\anaconda3\\lib\\site-packages\\matplotlib\\scale.py\", line 22, in <module>\n",
      "    from matplotlib.ticker import (\n",
      "ImportError: cannot import name 'NullFormatter' from 'matplotlib.ticker' (C:\\Users\\yashd\\anaconda3\\lib\\site-packages\\matplotlib\\ticker.py)\n",
      "Traceback (most recent call last):\n",
      "  File \"C:\\Users\\yashd\\anaconda3\\lib\\site-packages\\IPython\\core\\interactiveshell.py\", line 3457, in run_code\n",
      "    exec(code_obj, self.user_global_ns, self.user_ns)\n",
      "  File \"C:\\Users\\yashd\\AppData\\Local\\Temp\\ipykernel_14992\\1699537367.py\", line 5, in <module>\n",
      "    import librosa.display\n",
      "  File \"C:\\Users\\yashd\\anaconda3\\lib\\site-packages\\librosa\\display.py\", line 90, in <module>\n",
      "    class TimeFormatter(mplticker.Formatter):\n",
      "  File \"C:\\Users\\yashd\\anaconda3\\lib\\importlib\\util.py\", line 245, in __getattribute__\n",
      "    self.__spec__.loader.exec_module(self)\n",
      "  File \"C:\\Users\\yashd\\anaconda3\\lib\\site-packages\\matplotlib\\ticker.py\", line 138, in <module>\n",
      "    from matplotlib import transforms as mtransforms\n",
      "  File \"C:\\Users\\yashd\\anaconda3\\lib\\site-packages\\matplotlib\\transforms.py\", line 49, in <module>\n",
      "    from matplotlib._path import (\n",
      "ImportError: DLL load failed while importing _path: The specified module could not be found.\n",
      "\n",
      "During handling of the above exception, another exception occurred:\n",
      "\n",
      "Traceback (most recent call last):\n",
      "  File \"C:\\Users\\yashd\\anaconda3\\lib\\site-packages\\IPython\\core\\interactiveshell.py\", line 2077, in showtraceback\n",
      "    stb = value._render_traceback_()\n",
      "AttributeError: 'ImportError' object has no attribute '_render_traceback_'\n",
      "\n",
      "During handling of the above exception, another exception occurred:\n",
      "\n",
      "Traceback (most recent call last):\n",
      "  File \"C:\\Users\\yashd\\anaconda3\\lib\\site-packages\\IPython\\core\\interactiveshell.py\", line 3377, in run_ast_nodes\n",
      "    if (await self.run_code(code, result,  async_=asy)):\n",
      "  File \"C:\\Users\\yashd\\anaconda3\\lib\\site-packages\\IPython\\core\\interactiveshell.py\", line 3474, in run_code\n",
      "    self.showtraceback(running_compiled_code=True)\n",
      "  File \"C:\\Users\\yashd\\anaconda3\\lib\\site-packages\\IPython\\core\\interactiveshell.py\", line 2079, in showtraceback\n",
      "    stb = self.InteractiveTB.structured_traceback(etype,\n",
      "  File \"C:\\Users\\yashd\\anaconda3\\lib\\site-packages\\IPython\\core\\ultratb.py\", line 1367, in structured_traceback\n",
      "    return FormattedTB.structured_traceback(\n",
      "  File \"C:\\Users\\yashd\\anaconda3\\lib\\site-packages\\IPython\\core\\ultratb.py\", line 1267, in structured_traceback\n",
      "    return VerboseTB.structured_traceback(\n",
      "  File \"C:\\Users\\yashd\\anaconda3\\lib\\site-packages\\IPython\\core\\ultratb.py\", line 1124, in structured_traceback\n",
      "    formatted_exception = self.format_exception_as_a_whole(etype, evalue, etb, number_of_lines_of_context,\n",
      "  File \"C:\\Users\\yashd\\anaconda3\\lib\\site-packages\\IPython\\core\\ultratb.py\", line 1082, in format_exception_as_a_whole\n",
      "    last_unique, recursion_repeat = find_recursion(orig_etype, evalue, records)\n",
      "  File \"C:\\Users\\yashd\\anaconda3\\lib\\site-packages\\IPython\\core\\ultratb.py\", line 382, in find_recursion\n",
      "    return len(records), 0\n",
      "TypeError: object of type 'NoneType' has no len()\n",
      "\n",
      "During handling of the above exception, another exception occurred:\n",
      "\n",
      "Traceback (most recent call last):\n",
      "  File \"C:\\Users\\yashd\\anaconda3\\lib\\site-packages\\IPython\\core\\interactiveshell.py\", line 2077, in showtraceback\n",
      "    stb = value._render_traceback_()\n",
      "AttributeError: 'TypeError' object has no attribute '_render_traceback_'\n",
      "\n",
      "During handling of the above exception, another exception occurred:\n",
      "\n",
      "Traceback (most recent call last):\n",
      "  File \"C:\\Users\\yashd\\anaconda3\\lib\\site-packages\\IPython\\core\\interactiveshell.py\", line 2960, in _run_cell\n",
      "    return runner(coro)\n",
      "  File \"C:\\Users\\yashd\\anaconda3\\lib\\site-packages\\IPython\\core\\async_helpers.py\", line 78, in _pseudo_sync_runner\n",
      "    coro.send(None)\n",
      "  File \"C:\\Users\\yashd\\anaconda3\\lib\\site-packages\\IPython\\core\\interactiveshell.py\", line 3185, in run_cell_async\n",
      "    has_raised = await self.run_ast_nodes(code_ast.body, cell_name,\n",
      "  File \"C:\\Users\\yashd\\anaconda3\\lib\\site-packages\\IPython\\core\\interactiveshell.py\", line 3396, in run_ast_nodes\n",
      "    self.showtraceback()\n",
      "  File \"C:\\Users\\yashd\\anaconda3\\lib\\site-packages\\IPython\\core\\interactiveshell.py\", line 2079, in showtraceback\n",
      "    stb = self.InteractiveTB.structured_traceback(etype,\n",
      "  File \"C:\\Users\\yashd\\anaconda3\\lib\\site-packages\\IPython\\core\\ultratb.py\", line 1367, in structured_traceback\n",
      "    return FormattedTB.structured_traceback(\n",
      "  File \"C:\\Users\\yashd\\anaconda3\\lib\\site-packages\\IPython\\core\\ultratb.py\", line 1267, in structured_traceback\n",
      "    return VerboseTB.structured_traceback(\n",
      "  File \"C:\\Users\\yashd\\anaconda3\\lib\\site-packages\\IPython\\core\\ultratb.py\", line 1142, in structured_traceback\n",
      "    formatted_exceptions += self.format_exception_as_a_whole(etype, evalue, etb, lines_of_context,\n",
      "  File \"C:\\Users\\yashd\\anaconda3\\lib\\site-packages\\IPython\\core\\ultratb.py\", line 1082, in format_exception_as_a_whole\n",
      "    last_unique, recursion_repeat = find_recursion(orig_etype, evalue, records)\n",
      "  File \"C:\\Users\\yashd\\anaconda3\\lib\\site-packages\\IPython\\core\\ultratb.py\", line 382, in find_recursion\n",
      "    return len(records), 0\n",
      "TypeError: object of type 'NoneType' has no len()\n",
      "\n",
      "During handling of the above exception, another exception occurred:\n",
      "\n",
      "Traceback (most recent call last):\n",
      "  File \"C:\\Users\\yashd\\anaconda3\\lib\\site-packages\\IPython\\core\\interactiveshell.py\", line 2077, in showtraceback\n",
      "    stb = value._render_traceback_()\n",
      "AttributeError: 'TypeError' object has no attribute '_render_traceback_'\n",
      "\n",
      "During handling of the above exception, another exception occurred:\n",
      "\n",
      "Traceback (most recent call last):\n",
      "  File \"C:\\Users\\yashd\\anaconda3\\lib\\site-packages\\IPython\\core\\ultratb.py\", line 1101, in get_records\n",
      "    return _fixed_getinnerframes(etb, number_of_lines_of_context, tb_offset)\n",
      "  File \"C:\\Users\\yashd\\anaconda3\\lib\\site-packages\\IPython\\core\\ultratb.py\", line 248, in wrapped\n",
      "    return f(*args, **kwargs)\n",
      "  File \"C:\\Users\\yashd\\anaconda3\\lib\\site-packages\\IPython\\core\\ultratb.py\", line 281, in _fixed_getinnerframes\n",
      "    records = fix_frame_records_filenames(inspect.getinnerframes(etb, context))\n",
      "  File \"C:\\Users\\yashd\\anaconda3\\lib\\inspect.py\", line 1543, in getinnerframes\n",
      "    frameinfo = (tb.tb_frame,) + getframeinfo(tb, context)\n",
      "  File \"C:\\Users\\yashd\\anaconda3\\lib\\inspect.py\", line 1501, in getframeinfo\n",
      "    filename = getsourcefile(frame) or getfile(frame)\n",
      "  File \"C:\\Users\\yashd\\anaconda3\\lib\\inspect.py\", line 709, in getsourcefile\n",
      "    if getattr(getmodule(object, filename), '__loader__', None) is not None:\n",
      "  File \"C:\\Users\\yashd\\anaconda3\\lib\\inspect.py\", line 746, in getmodule\n",
      "    if ismodule(module) and hasattr(module, '__file__'):\n",
      "  File \"C:\\Users\\yashd\\anaconda3\\lib\\importlib\\util.py\", line 245, in __getattribute__\n",
      "    self.__spec__.loader.exec_module(self)\n",
      "  File \"<frozen importlib._bootstrap_external>\", line 850, in exec_module\n",
      "  File \"<frozen importlib._bootstrap>\", line 228, in _call_with_frames_removed\n",
      "  File \"C:\\Users\\yashd\\anaconda3\\lib\\site-packages\\matplotlib\\pyplot.py\", line 52, in <module>\n",
      "    import matplotlib.colorbar\n",
      "  File \"C:\\Users\\yashd\\anaconda3\\lib\\site-packages\\matplotlib\\colorbar.py\", line 19, in <module>\n",
      "    from matplotlib import _api, cbook, collections, cm, colors, contour, ticker\n",
      "  File \"C:\\Users\\yashd\\anaconda3\\lib\\site-packages\\matplotlib\\collections.py\", line 19, in <module>\n",
      "    from . import (_api, _path, artist, cbook, cm, colors as mcolors, _docstring,\n",
      "ImportError: DLL load failed while importing _path: The specified module could not be found.\n"
     ]
    }
   ],
   "source": [
    "## import libraries\n",
    "\n",
    "# this is library which is use to prerprocess the audio data and also nommalize the data\n",
    "import librosa\n",
    "import librosa.display\n",
    "\n",
    "## this is the library which is use to display the audio data\n",
    "import IPython.display as ipd\n",
    "\n",
    "# scipy.io is also the library which with the help we can prepross the audio data but it dosen't normalize the data\n",
    "from scipy.io import wavfile as wav\n"
   ]
  },
  {
   "cell_type": "code",
   "execution_count": null,
   "id": "c547a6a2",
   "metadata": {},
   "outputs": [],
   "source": []
  },
  {
   "cell_type": "code",
   "execution_count": null,
   "id": "1e52899a",
   "metadata": {
    "scrolled": true
   },
   "outputs": [],
   "source": [
    "# visualization libraries\n",
    "import matplotlib.pyplot as plt\n",
    "import seaborn as sns\n",
    "%matplotlib inline"
   ]
  },
  {
   "cell_type": "markdown",
   "id": "e0660278",
   "metadata": {},
   "source": [
    "### reading the audio file"
   ]
  },
  {
   "cell_type": "code",
   "execution_count": null,
   "id": "74d5dfec",
   "metadata": {},
   "outputs": [],
   "source": [
    "filepath = \"free-spoken-digit-dataset-master/recordings/0_george_0.wav\""
   ]
  },
  {
   "cell_type": "code",
   "execution_count": null,
   "id": "40744ae2",
   "metadata": {},
   "outputs": [],
   "source": [
    "# !dir"
   ]
  },
  {
   "cell_type": "code",
   "execution_count": null,
   "id": "0485d1df",
   "metadata": {},
   "outputs": [],
   "source": [
    "# loading a file with the help of librosa\n",
    "data, sample_rate = librosa.load(filepath)\n",
    "print(sample_rate)\n",
    "\n",
    "# loading a file with the help of scipy\n",
    "# wav_sample_rate, wav_data = wav\n",
    "# print(wav_sample_rate)"
   ]
  },
  {
   "cell_type": "code",
   "execution_count": null,
   "id": "28810844",
   "metadata": {},
   "outputs": [],
   "source": [
    "## visualizing the audio\n",
    "plt.figure(figsize=(10,5))\n",
    "librosa.display.waveshow(data, sr=sample_rate)\n",
    "ipd.Audio(filepath)\n"
   ]
  },
  {
   "cell_type": "code",
   "execution_count": null,
   "id": "d87623d0",
   "metadata": {},
   "outputs": [],
   "source": []
  },
  {
   "cell_type": "code",
   "execution_count": null,
   "id": "5a33a28a",
   "metadata": {},
   "outputs": [],
   "source": []
  },
  {
   "cell_type": "code",
   "execution_count": null,
   "id": "2eafe40a",
   "metadata": {},
   "outputs": [],
   "source": []
  },
  {
   "cell_type": "code",
   "execution_count": null,
   "id": "1d830300",
   "metadata": {},
   "outputs": [],
   "source": []
  }
 ],
 "metadata": {
  "kernelspec": {
   "display_name": "Python 3 (ipykernel)",
   "language": "python",
   "name": "python3"
  },
  "language_info": {
   "codemirror_mode": {
    "name": "ipython",
    "version": 3
   },
   "file_extension": ".py",
   "mimetype": "text/x-python",
   "name": "python",
   "nbconvert_exporter": "python",
   "pygments_lexer": "ipython3",
   "version": "3.9.13"
  }
 },
 "nbformat": 4,
 "nbformat_minor": 5
}
